<?xml version="1.0" ?>
<robot name="wheeltec_robot">

    <link name="base_link">
        <visual>
            <origin xyz=" 0 0 0.10" rpy="0 0 0" />
            <geometry>
		    <box size="0.35 0.34 0.10"/>
            </geometry>
            <material name="white">
                <color rgba="1 1 1 1"/>
            </material>
        </visual>
    </link>   

    <joint name="left_wheel_joint" type="continuous">
        <origin xyz="-0.095 0.185 0.05" rpy="1.57 0 0"/>
        <parent link="base_link"/>
        <child link="left_wheel_link"/>
        <axis xyz="0 1 0"/>
    </joint>

    <link name="left_wheel_link">
        <visual>
            <origin xyz="0 0 0" rpy="0 0 0" />
            <geometry>
                <cylinder radius="0.05" length = "0.04"/>
            </geometry>
            <material name="black">
                <color rgba="0 0 0 1"/>
            </material>
        </visual>
    </link>

    <joint name="right_wheel_joint" type="continuous">
        <origin xyz="-0.095 -0.185 0.05" rpy="1.57 0 0"/>
        <parent link="base_link"/>
        <child link="right_wheel_link"/>
        <axis xyz="0 1 0"/>
    </joint>

    <link name="right_wheel_link">
        <visual>
            <origin xyz="0 0 0" rpy="0 0 0" />
            <geometry>
                <cylinder radius="0.05" length = "0.04"/>
            </geometry>
            <material name="black">
                <color rgba="0 0 0 1"/>
            </material>
        </visual>
    </link>

      <joint name="left_front_joint" type="continuous">
        <origin xyz="0.095 0.185 0.05" rpy="1.57 0 0"/>
        <parent link="base_link"/>
        <child link="left_front_link"/>
        <axis xyz="0 1 0"/>
    </joint>

    <link name="left_front_link">
        <visual>
            <origin xyz="0 0 0" rpy="0 0 0" />
            <geometry>
                <cylinder radius="0.05" length = "0.04"/>
            </geometry>
            <material name="black">
                <color rgba="0 0 0 1"/>
            </material>
        </visual>
    </link>

    <joint name="right_front_joint" type="continuous">
        <origin xyz="0.095 -0.185 0.05" rpy="1.57 0 0"/>
        <parent link="base_link"/>
        <child link="right_front_link"/>
        <axis xyz="0 1 0"/>
    </joint>

    <link name="right_front_link">
        <visual>
            <origin xyz="0 0 0" rpy="0 0 0" />
            <geometry>
                <cylinder radius="0.05" length = "0.04"/>
            </geometry>
            <material name="black">
                <color rgba="0 0 0 1"/>
            </material>
        </visual>
    </link>


	<!-- holder --> 
        <link name="holder_link">
	        <visual>
			<origin xyz="0 0 0" rpy="0 0 0" />
			<geometry>
				<box size="0.04 0.1 0.85" />
			</geometry>
			<material name="white">
				<color rgba="1 1 1 1"/>
			</material>
		</visual>
	</link>

	<joint name="base_to_holder" type="fixed">
		<origin xyz="0 0 0.575" rpy="0 0 0"/>
		<parent link="base_link"/>
		<child link="holder_link"/>
	</joint>

	

	<!-- usb_camera -->
        <link name="usb_cam">
                <visual>
                        <origin xyz="0 0 0" rpy="0 0 0" />
			<geometry>
				<cylinder radius="0.01" length="0.02" />
                        </geometry>
                        <material name="black">
                                <color rgba="0 0 0 1"/>
                        </material>
                </visual>
        </link>

        <joint name="base_to_cam" type="fixed">
                <origin xyz="0.03 0 0.95" rpy="0 0 0"/>
                <parent link="base_link"/>
                <child link="usb_cam"/>
        </joint>

	 <!-- depth_camera -->
        <link name="camera_link">
                <visual>
                        <origin xyz="0 0 0" rpy="0 0 0" />
                        <geometry>
                                <box size="0.03 0.08 0.03" />
                        </geometry>
                        <material name="black">
                                <color rgba="0 0 0 1"/>
                        </material>
                </visual>
        </link>

        <joint name="base_to_camera" type="fixed">
                <origin xyz="0.035 0 0.71" rpy="0 0 0"/>
                <parent link="base_link"/>
                <child link="camera_link"/>
        </joint>


        <!-- IMU -->
    	<link name="gyro_link">
		<visual>
			<origin xyz="0 0.13 0.175" rpy="1.57 0 0" />
	    		<geometry>
				<box size="0.05 0.05 0.02" />
			</geometry>
			<material name="black">
				<color rgba="0 0 0 1" />
			</material>
		</visual>
	</link>
	
	<joint name="gyro_to_base" type="fixed" >
		<origin xyz="0 0 0" rpy="0 0 0" />
		<parent link="base_link" />
		<child link="gyro_link" />
	</joint>


	<!-- laser -->
	<joint name="laser_to_base" type="fixed" >
		<origin xyz="0.13 0 0.168" rpy="0 0 3.14" />
		<parent link="base_link" />
		<child link="laser" />
	</joint>

	<link name="laser">
                <visual>
                        <origin xyz="0 0 0" rpy="0 0 0" />
                        <geometry>
                                <cylinder radius="0.038" length="0.036" />
                        </geometry>
                        <material name="black">
                                <color rgba="0 0 0 1" />
                        </material>
                </visual>
        </link>
	

</robot>
